Traceback (most recent call last):
  File "<frozen runpy>", line 198, in _run_module_as_main
  File "<frozen runpy>", line 88, in _run_code
  File "/usr/lib/python3.11/http/server.py", line 1309, in <module>
    test(
  File "/usr/lib/python3.11/http/server.py", line 1256, in test
    with ServerClass(addr, HandlerClass) as httpd:
         ^^^^^^^^^^^^^^^^^^^^^^^^^^^^^^^
  File "/usr/lib/python3.11/socketserver.py", line 456, in __init__
    self.server_bind()
  File "/usr/lib/python3.11/http/server.py", line 1303, in server_bind
    return super().server_bind()
           ^^^^^^^^^^^^^^^^^^^^^
  File "/usr/lib/python3.11/http/server.py", line 136, in server_bind
    socketserver.TCPServer.server_bind(self)
  File "/usr/lib/python3.11/socketserver.py", line 472, in server_bind
    self.socket.bind(self.server_address)
OSError: [Errno 98] Address already in use
127.0.0.1 - - [01/Aug/2024 08:00:48] "GET /test.html HTTP/1.1" 304 -
127.0.0.1 - - [01/Aug/2024 08:01:03] "GET /test.html HTTP/1.1" 200 -
127.0.0.1 - - [01/Aug/2024 08:01:04] code 404, message File not found
127.0.0.1 - - [01/Aug/2024 08:01:04] "GET /test.htmlfavicon.ico HTTP/1.1" 404 -
127.0.0.1 - - [01/Aug/2024 08:14:04] "GET /test.html HTTP/1.1" 200 -
----------------------------------------
Exception occurred during processing of request from ('162.142.125.196', 50436)
Traceback (most recent call last):
  File "/usr/lib/python3.11/socketserver.py", line 691, in process_request_thread
    self.finish_request(request, client_address)
  File "/usr/lib/python3.11/http/server.py", line 1306, in finish_request
    self.RequestHandlerClass(request, client_address, self,
  File "/usr/lib/python3.11/http/server.py", line 667, in __init__
    super().__init__(*args, **kwargs)
  File "/usr/lib/python3.11/socketserver.py", line 755, in __init__
    self.handle()
  File "/usr/lib/python3.11/http/server.py", line 432, in handle
    self.handle_one_request()
  File "/usr/lib/python3.11/http/server.py", line 400, in handle_one_request
    self.raw_requestline = self.rfile.readline(65537)
                           ^^^^^^^^^^^^^^^^^^^^^^^^^^
  File "/usr/lib/python3.11/socket.py", line 706, in readinto
    return self._sock.recv_into(b)
           ^^^^^^^^^^^^^^^^^^^^^^^
ConnectionResetError: [Errno 104] Connection reset by peer
----------------------------------------
162.142.125.196 - - [01/Aug/2024 08:45:07] "GET / HTTP/1.1" 200 -
162.142.125.196 - - [01/Aug/2024 08:45:11] "GET / HTTP/1.1" 200 -
162.142.125.196 - - [01/Aug/2024 08:45:12] code 404, message File not found
162.142.125.196 - - [01/Aug/2024 08:45:12] "GET /favicon.ico HTTP/1.1" 404 -
162.142.125.196 - - [01/Aug/2024 08:45:12] code 505, message Invalid HTTP version (2.0)
162.142.125.196 - - [01/Aug/2024 08:45:12] "PRI * HTTP/2.0" 505 -
127.0.0.1 - - [01/Aug/2024 08:54:29] code 404, message File not found
127.0.0.1 - - [01/Aug/2024 08:54:29] "GET /test.htmlgeoserver/web HTTP/1.1" 404 -
127.0.0.1 - - [01/Aug/2024 09:54:31] "GET /test.html HTTP/1.1" 200 -
127.0.0.1 - - [01/Aug/2024 09:55:06] code 404, message File not found
127.0.0.1 - - [01/Aug/2024 09:55:06] "GET /test.htmlfavicon.ico HTTP/1.1" 404 -
127.0.0.1 - - [01/Aug/2024 10:47:56] "GET /test.html HTTP/1.1" 200 -
127.0.0.1 - - [01/Aug/2024 11:09:53] code 404, message File not found
127.0.0.1 - - [01/Aug/2024 11:09:53] "GET /test.htmllogin.jsp HTTP/1.1" 404 -
127.0.0.1 - - [01/Aug/2024 11:26:56] "GET /test.html HTTP/1.1" 200 -
127.0.0.1 - - [01/Aug/2024 11:27:12] code 404, message File not found
127.0.0.1 - - [01/Aug/2024 11:27:12] "GET /test.htmlfavicon.ico HTTP/1.1" 404 -
127.0.0.1 - - [01/Aug/2024 12:14:29] code 404, message File not found
127.0.0.1 - - [01/Aug/2024 12:14:29] "GET /test.htmlfavicon.ico HTTP/1.1" 404 -
